Workbook
Name _11__2: #REF!
Name bbss: 0.533

Sheet G.G.Variables
E2: GASTOS GENERALES VARIABLES DEL PAQUETE 08
E4: =+'[1]Res. G.G'!E3 -> “CONSTRUCCIÓN DEL SISTEMA DE DRENAJE URBANO EN EL SECTOR JESÚS MARÍA – CANAL Y OBRAS DE ESTABILIZACIÓN EN LAS LADERAS DEL SECTOR JESÚS MARÍA (PAQUETE 08)” | F4: =+'[1]Res. G.G'!K4 -> 45894
C7: ANÁLISIS DE GASTOS GENERALES VARIABLES
C8: ='[1]Res. G.G'!E8 -> 9.5
C11: ÍTEM | D11: CUENTA COSTOS | E11: DESCRIPCIÓN | F11: P. PARCIAL (S)
C12: 1 | D12: PQ.08.601 | E12: REMUNERACIÓN PERSONAL PROFESIONAL-TECNICO-ADMINISTRATIVO-AUXILIAR, INCLUYE BENEFICIOS SOCIALES | F12: 3384414.4 | M12: EJECUCIÓN | W12: CIERRE COMERCIAL | Z12: TOTAL
C13: 1.01 | E13: REMUNERACIÓN PERSONAL PROFESIONAL | F13: 2863579.3 | M13: MES 1 | N13: MES 2 | O13: MES 3 | P13: MES 4 | Q13: MES 5 | R13: MES 6 | S13: MES 7 | T13: MES 8 | U13: MES 9 | V13: MES 10 | W13: MES 12 | X13: MES 13
C14: 1.01.01 | E14: Ingeniero Residente de Obra (*) | F14: 331733.41 | J14: 19000 | K14: =+IF(#REF!="FORÁNEO",J14+1750,J14) -> #REF! | M14: =+'G.G.Variables'!#REF!*[1]Histograma!I11 -> #REF! | N14: =+'G.G.Variables'!#REF!*[1]Histograma!J11 -> #REF! | O14: =+'G.G.Variables'!#REF!*[1]Histograma!K11 -> #REF! | P14: =+'G.G.Variables'!#REF!*[1]Histograma!L11 -> #REF! | Q14: =+'G.G.Variables'!#REF!*[1]Histograma!M11 -> #REF! | R14: =+'G.G.Variables'!#REF!*[1]Histograma!N11 -> #REF! | S14: =+'G.G.Variables'!#REF!*[1]Histograma!O11 -> #REF! | T14: =+'G.G.Variables'!#REF!*[1]Histograma!P11 -> #REF! | ... X14: =+'G.G.Variables'!#REF!*[1]Histograma!T11 -> #REF! | Z14: =+SUM(M14:X14) -> #REF!
C15: 1.01.02 | E15: Jefe de Producción | F15: 140155.83 | J15: 12000 | K15: =+IF(#REF!="FORÁNEO",J15+1750,J15) -> #REF! | M15: =+'G.G.Variables'!#REF!*[1]Histograma!I12 -> #REF! | N15: =+'G.G.Variables'!#REF!*[1]Histograma!J12 -> #REF! | O15: =+'G.G.Variables'!#REF!*[1]Histograma!K12 -> #REF! | P15: =+'G.G.Variables'!#REF!*[1]Histograma!L12 -> #REF! | Q15: =+'G.G.Variables'!#REF!*[1]Histograma!M12 -> #REF! | R15: =+'G.G.Variables'!#REF!*[1]Histograma!N12 -> #REF! | S15: =+'G.G.Variables'!#REF!*[1]Histograma!O12 -> #REF! | T15: =+'G.G.Variables'!#REF!*[1]Histograma!P12 -> #REF! | ... X15: =+'G.G.Variables'!#REF!*[1]Histograma!T12 -> #REF! | Z15: =+SUM(M15:X15) -> #REF!
C16: 1.01.03 | E16: Ingeniero de Producción 1 | F16: 102758.74 | J16: 10000 | K16: =+IF(#REF!="FORÁNEO",J16+1750,J16) -> #REF! | M16: =+'G.G.Variables'!#REF!*[1]Histograma!I13 -> #REF! | N16: =+'G.G.Variables'!#REF!*[1]Histograma!J13 -> #REF! | O16: =+'G.G.Variables'!#REF!*[1]Histograma!K13 -> #REF! | P16: =+'G.G.Variables'!#REF!*[1]Histograma!L13 -> #REF! | Q16: =+'G.G.Variables'!#REF!*[1]Histograma!M13 -> #REF! | R16: =+'G.G.Variables'!#REF!*[1]Histograma!N13 -> #REF! | S16: =+'G.G.Variables'!#REF!*[1]Histograma!O13 -> #REF! | T16: =+'G.G.Variables'!#REF!*[1]Histograma!P13 -> #REF! | ... X16: =+'G.G.Variables'!#REF!*[1]Histograma!T13 -> #REF! | Z16: =+SUM(M16:X16) -> #REF!
C17: 1.01.04 | E17: Ingeniero de Producción 2 | F17: 102758.74 | M17: =+'G.G.Variables'!#REF!*[1]Histograma!I14 -> #REF! | N17: =+'G.G.Variables'!#REF!*[1]Histograma!J14 -> #REF! | O17: =+'G.G.Variables'!#REF!*[1]Histograma!K14 -> #REF! | P17: =+'G.G.Variables'!#REF!*[1]Histograma!L14 -> #REF! | Q17: =+'G.G.Variables'!#REF!*[1]Histograma!M14 -> #REF! | R17: =+'G.G.Variables'!#REF!*[1]Histograma!N14 -> #REF! | S17: =+'G.G.Variables'!#REF!*[1]Histograma!O14 -> #REF! | T17: =+'G.G.Variables'!#REF!*[1]Histograma!P14 -> #REF! | ... X17: =+'G.G.Variables'!#REF!*[1]Histograma!T14 -> #REF! | Z17: =+SUM(M17:X17) -> #REF!
C18: 1.01.05 | E18: Jefe de Oficina Técnica (*) | F18: 228208.35 | J18: 12000 | K18: =+IF(#REF!="FORÁNEO",J18+1750,J18) -> #REF! | M18: =+'G.G.Variables'!#REF!*[1]Histograma!I15 -> #REF! | N18: =+'G.G.Variables'!#REF!*[1]Histograma!J15 -> #REF! | O18: =+'G.G.Variables'!#REF!*[1]Histograma!K15 -> #REF! | P18: =+'G.G.Variables'!#REF!*[1]Histograma!L15 -> #REF! | Q18: =+'G.G.Variables'!#REF!*[1]Histograma!M15 -> #REF! | R18: =+'G.G.Variables'!#REF!*[1]Histograma!N15 -> #REF! | S18: =+'G.G.Variables'!#REF!*[1]Histograma!O15 -> #REF! | T18: =+'G.G.Variables'!#REF!*[1]Histograma!P15 -> #REF! | ... X18: =+'G.G.Variables'!#REF!*[1]Histograma!T15 -> #REF! | Z18: =+SUM(M18:X18) -> #REF!
C19: 1.01.06 | E19: Ingeniero de Metrados y Valorizaciones (*) | F19: 188391.02 | J19: 10000 | K19: =+IF(#REF!="FORÁNEO",J19+1750,J19) -> #REF! | M19: =+'G.G.Variables'!#REF!*[1]Histograma!I16 -> #REF! | N19: =+'G.G.Variables'!#REF!*[1]Histograma!J16 -> #REF! | O19: =+'G.G.Variables'!#REF!*[1]Histograma!K16 -> #REF! | P19: =+'G.G.Variables'!#REF!*[1]Histograma!L16 -> #REF! | Q19: =+'G.G.Variables'!#REF!*[1]Histograma!M16 -> #REF! | R19: =+'G.G.Variables'!#REF!*[1]Histograma!N16 -> #REF! | S19: =+'G.G.Variables'!#REF!*[1]Histograma!O16 -> #REF! | T19: =+'G.G.Variables'!#REF!*[1]Histograma!P16 -> #REF! | ... X19: =+'G.G.Variables'!#REF!*[1]Histograma!T16 -> #REF! | Z19: =+SUM(M19:X19) -> #REF!
C20: 1.01.07 | E20: Ingeniero de Planemiento y Programación | F20: 154138.1 | J20: 10000 | K20: =+IF(#REF!="FORÁNEO",J20+1750,J20) -> #REF! | M20: =+'G.G.Variables'!#REF!*[1]Histograma!I17 -> #REF! | N20: =+'G.G.Variables'!#REF!*[1]Histograma!J17 -> #REF! | O20: =+'G.G.Variables'!#REF!*[1]Histograma!K17 -> #REF! | P20: =+'G.G.Variables'!#REF!*[1]Histograma!L17 -> #REF! | Q20: =+'G.G.Variables'!#REF!*[1]Histograma!M17 -> #REF! | R20: =+'G.G.Variables'!#REF!*[1]Histograma!N17 -> #REF! | S20: =+'G.G.Variables'!#REF!*[1]Histograma!O17 -> #REF! | T20: =+'G.G.Variables'!#REF!*[1]Histograma!P17 -> #REF! | ... X20: =+'G.G.Variables'!#REF!*[1]Histograma!T17 -> #REF! | Z20: =+SUM(M20:X20) -> #REF!
C21: 1.01.08 | E21: Ingeniero Ambiental | F21: 102758.74 | J21: 10000 | K21: =+IF(#REF!="FORÁNEO",J21+1750,J21) -> #REF! | M21: =+'G.G.Variables'!#REF!*[1]Histograma!I18 -> #REF! | N21: =+'G.G.Variables'!#REF!*[1]Histograma!J18 -> #REF! | O21: =+'G.G.Variables'!#REF!*[1]Histograma!K18 -> #REF! | P21: =+'G.G.Variables'!#REF!*[1]Histograma!L18 -> #REF! | Q21: =+'G.G.Variables'!#REF!*[1]Histograma!M18 -> #REF! | R21: =+'G.G.Variables'!#REF!*[1]Histograma!N18 -> #REF! | S21: =+'G.G.Variables'!#REF!*[1]Histograma!O18 -> #REF! | T21: =+'G.G.Variables'!#REF!*[1]Histograma!P18 -> #REF! | ... X21: =+'G.G.Variables'!#REF!*[1]Histograma!T18 -> #REF! | Z21: =+SUM(M21:X21) -> #REF!
C22: 1.01.09 | E22: Responsable SSOMA 1 | F22: 162701.33 | J22: 10000 | K22: =+IF(#REF!="FORÁNEO",J22+1750,J22) -> #REF! | M22: =+'G.G.Variables'!#REF!*[1]Histograma!I19 -> #REF! | N22: =+'G.G.Variables'!#REF!*[1]Histograma!J19 -> #REF! | O22: =+'G.G.Variables'!#REF!*[1]Histograma!K19 -> #REF! | P22: =+'G.G.Variables'!#REF!*[1]Histograma!L19 -> #REF! | Q22: =+'G.G.Variables'!#REF!*[1]Histograma!M19 -> #REF! | R22: =+'G.G.Variables'!#REF!*[1]Histograma!N19 -> #REF! | S22: =+'G.G.Variables'!#REF!*[1]Histograma!O19 -> #REF! | T22: =+'G.G.Variables'!#REF!*[1]Histograma!P19 -> #REF! | ... X22: =+'G.G.Variables'!#REF!*[1]Histograma!T19 -> #REF! | Z22: =+SUM(M22:X22) -> #REF!
C23: 1.01.10 | E23: Responsable SSOMA 2 | F23: 162701.33 | M23: =+'G.G.Variables'!#REF!*[1]Histograma!I20 -> #REF! | N23: =+'G.G.Variables'!#REF!*[1]Histograma!J20 -> #REF! | O23: =+'G.G.Variables'!#REF!*[1]Histograma!K20 -> #REF! | P23: =+'G.G.Variables'!#REF!*[1]Histograma!L20 -> #REF! | Q23: =+'G.G.Variables'!#REF!*[1]Histograma!M20 -> #REF! | R23: =+'G.G.Variables'!#REF!*[1]Histograma!N20 -> #REF! | S23: =+'G.G.Variables'!#REF!*[1]Histograma!O20 -> #REF! | T23: =+'G.G.Variables'!#REF!*[1]Histograma!P20 -> #REF! | ... X23: =+'G.G.Variables'!#REF!*[1]Histograma!T20 -> #REF! | Z23: =+SUM(M23:X23) -> #REF!
C24: 1.01.11 | E24: Prevencionista de obra 1 | F24: 90678.75 | J24: 7000 | K24: =+IF(#REF!="FORÁNEO",J24+1750,J24) -> #REF! | M24: =+'G.G.Variables'!#REF!*[1]Histograma!I21 -> #REF! | N24: =+'G.G.Variables'!#REF!*[1]Histograma!J21 -> #REF! | O24: =+'G.G.Variables'!#REF!*[1]Histograma!K21 -> #REF! | P24: =+'G.G.Variables'!#REF!*[1]Histograma!L21 -> #REF! | Q24: =+'G.G.Variables'!#REF!*[1]Histograma!M21 -> #REF! | R24: =+'G.G.Variables'!#REF!*[1]Histograma!N21 -> #REF! | S24: =+'G.G.Variables'!#REF!*[1]Histograma!O21 -> #REF! | T24: =+'G.G.Variables'!#REF!*[1]Histograma!P21 -> #REF! | ... X24: =+'G.G.Variables'!#REF!*[1]Histograma!T21 -> #REF! | Z24: =+SUM(M24:X24) -> #REF!
C25: 1.01.12 | E25: Prevencionista de obra 2 | F25: 90678.75 | M25: =+'G.G.Variables'!#REF!*[1]Histograma!I22 -> #REF! | N25: =+'G.G.Variables'!#REF!*[1]Histograma!J22 -> #REF! | O25: =+'G.G.Variables'!#REF!*[1]Histograma!K22 -> #REF! | P25: =+'G.G.Variables'!#REF!*[1]Histograma!L22 -> #REF! | Q25: =+'G.G.Variables'!#REF!*[1]Histograma!M22 -> #REF! | R25: =+'G.G.Variables'!#REF!*[1]Histograma!N22 -> #REF! | S25: =+'G.G.Variables'!#REF!*[1]Histograma!O22 -> #REF! | T25: =+'G.G.Variables'!#REF!*[1]Histograma!P22 -> #REF! | ... X25: =+'G.G.Variables'!#REF!*[1]Histograma!T22 -> #REF! | Z25: =+SUM(M25:X25) -> #REF!
C26: 1.01.13 | E26: Especialista BIM | F26: 220244.88 | J26: 12000 | K26: =+IF(#REF!="FORÁNEO",J26+1750,J26) -> #REF! | M26: =+'G.G.Variables'!#REF!*[1]Histograma!I23 -> #REF! | N26: =+'G.G.Variables'!#REF!*[1]Histograma!J23 -> #REF! | O26: =+'G.G.Variables'!#REF!*[1]Histograma!K23 -> #REF! | P26: =+'G.G.Variables'!#REF!*[1]Histograma!L23 -> #REF! | Q26: =+'G.G.Variables'!#REF!*[1]Histograma!M23 -> #REF! | R26: =+'G.G.Variables'!#REF!*[1]Histograma!N23 -> #REF! | S26: =+'G.G.Variables'!#REF!*[1]Histograma!O23 -> #REF! | T26: =+'G.G.Variables'!#REF!*[1]Histograma!P23 -> #REF! | ... X26: =+'G.G.Variables'!#REF!*[1]Histograma!T23 -> #REF! | Z26: =+SUM(M26:X26) -> #REF!
C27: 1.01.14 | E27: Jefe de Calidad | F27: 171264.56 | J27: 11000 | K27: =+IF(#REF!="FORÁNEO",J27+1750,J27) -> #REF! | M27: =+'G.G.Variables'!#REF!*[1]Histograma!I24 -> #REF! | N27: =+'G.G.Variables'!#REF!*[1]Histograma!J24 -> #REF! | O27: =+'G.G.Variables'!#REF!*[1]Histograma!K24 -> #REF! | P27: =+'G.G.Variables'!#REF!*[1]Histograma!L24 -> #REF! | Q27: =+'G.G.Variables'!#REF!*[1]Histograma!M24 -> #REF! | R27: =+'G.G.Variables'!#REF!*[1]Histograma!N24 -> #REF! | S27: =+'G.G.Variables'!#REF!*[1]Histograma!O24 -> #REF! | T27: =+'G.G.Variables'!#REF!*[1]Histograma!P24 -> #REF! | ... X27: =+'G.G.Variables'!#REF!*[1]Histograma!T24 -> #REF! | Z27: =+SUM(M27:X27) -> #REF!
C28: 1.01.15 | E28: Ingeniero de Aseguramiento y Control de Calidad | F28: 125428.42 | J28: 9200 | K28: =+IF(#REF!="FORÁNEO",J28+1750,J28) -> #REF! | M28: =+'G.G.Variables'!#REF!*[1]Histograma!I25 -> #REF! | N28: =+'G.G.Variables'!#REF!*[1]Histograma!J25 -> #REF! | O28: =+'G.G.Variables'!#REF!*[1]Histograma!K25 -> #REF! | P28: =+'G.G.Variables'!#REF!*[1]Histograma!L25 -> #REF! | Q28: =+'G.G.Variables'!#REF!*[1]Histograma!M25 -> #REF! | R28: =+'G.G.Variables'!#REF!*[1]Histograma!N25 -> #REF! | S28: =+'G.G.Variables'!#REF!*[1]Histograma!O25 -> #REF! | T28: =+'G.G.Variables'!#REF!*[1]Histograma!P25 -> #REF! | ... X28: =+'G.G.Variables'!#REF!*[1]Histograma!T25 -> #REF! | Z28: =+SUM(M28:X28) -> #REF!
C29: 1.01.16 | E29: Asistente de Aseguramiento y Control de Calidad 1 | F29: 93533.36 | J29: 7400 | K29: =+IF(#REF!="FORÁNEO",J29+1750,J29) -> #REF! | M29: =+'G.G.Variables'!#REF!*[1]Histograma!I26 -> #REF! | N29: =+'G.G.Variables'!#REF!*[1]Histograma!J26 -> #REF! | O29: =+'G.G.Variables'!#REF!*[1]Histograma!K26 -> #REF! | P29: =+'G.G.Variables'!#REF!*[1]Histograma!L26 -> #REF! | Q29: =+'G.G.Variables'!#REF!*[1]Histograma!M26 -> #REF! | R29: =+'G.G.Variables'!#REF!*[1]Histograma!N26 -> #REF! | S29: =+'G.G.Variables'!#REF!*[1]Histograma!O26 -> #REF! | T29: =+'G.G.Variables'!#REF!*[1]Histograma!P26 -> #REF! | ... X29: =+'G.G.Variables'!#REF!*[1]Histograma!T26 -> #REF! | Z29: =+SUM(M29:X29) -> #REF!
C30: 1.01.17 | E30: Asistente de Aseguramiento y Control de Calidad 2 | F30: 93533.36 | M30: =+'G.G.Variables'!#REF!*[1]Histograma!I27 -> #REF! | N30: =+'G.G.Variables'!#REF!*[1]Histograma!J27 -> #REF! | O30: =+'G.G.Variables'!#REF!*[1]Histograma!K27 -> #REF! | P30: =+'G.G.Variables'!#REF!*[1]Histograma!L27 -> #REF! | Q30: =+'G.G.Variables'!#REF!*[1]Histograma!M27 -> #REF! | R30: =+'G.G.Variables'!#REF!*[1]Histograma!N27 -> #REF! | S30: =+'G.G.Variables'!#REF!*[1]Histograma!O27 -> #REF! | T30: =+'G.G.Variables'!#REF!*[1]Histograma!P27 -> #REF! | ... X30: =+'G.G.Variables'!#REF!*[1]Histograma!T27 -> #REF! | Z30: =+SUM(M30:X30) -> #REF!
C31: 1.01.18 | E31: Especialista Social | F31: 119885.19 | J31: 11000 | K31: =+IF(#REF!="FORÁNEO",J31+1750,J31) -> #REF! | M31: =+'G.G.Variables'!#REF!*[1]Histograma!I28 -> #REF! | N31: =+'G.G.Variables'!#REF!*[1]Histograma!J28 -> #REF! | O31: =+'G.G.Variables'!#REF!*[1]Histograma!K28 -> #REF! | P31: =+'G.G.Variables'!#REF!*[1]Histograma!L28 -> #REF! | Q31: =+'G.G.Variables'!#REF!*[1]Histograma!M28 -> #REF! | R31: =+'G.G.Variables'!#REF!*[1]Histograma!N28 -> #REF! | S31: =+'G.G.Variables'!#REF!*[1]Histograma!O28 -> #REF! | T31: =+'G.G.Variables'!#REF!*[1]Histograma!P28 -> #REF! | ... X31: =+'G.G.Variables'!#REF!*[1]Histograma!T28 -> #REF! | Z31: =+SUM(M31:X31) -> #REF!
C32: 1.01.19 | E32: Arqueólogo | F32: 113520.62 | J32: 11000 | K32: =+IF(#REF!="FORÁNEO",J32+1750,J32) -> #REF! | M32: =+'G.G.Variables'!#REF!*[1]Histograma!I29 -> #REF! | N32: =+'G.G.Variables'!#REF!*[1]Histograma!J29 -> #REF! | O32: =+'G.G.Variables'!#REF!*[1]Histograma!K29 -> #REF! | P32: =+'G.G.Variables'!#REF!*[1]Histograma!L29 -> #REF! | Q32: =+'G.G.Variables'!#REF!*[1]Histograma!M29 -> #REF! | R32: =+'G.G.Variables'!#REF!*[1]Histograma!N29 -> #REF! | S32: =+'G.G.Variables'!#REF!*[1]Histograma!O29 -> #REF! | T32: =+'G.G.Variables'!#REF!*[1]Histograma!P29 -> #REF! | ... X32: =+'G.G.Variables'!#REF!*[1]Histograma!T29 -> #REF! | Z32: =+SUM(M32:X32) -> #REF!
C33: 1.01.20 | E33: Arquitecto Paisajista | F33: 68505.82 | J33: 12326.08 | K33: =+IF(#REF!="FORÁNEO",J33+1750,J33) -> #REF! | M33: =+'G.G.Variables'!#REF!*[1]Histograma!I30 -> #REF! | N33: =+'G.G.Variables'!#REF!*[1]Histograma!J30 -> #REF! | O33: =+'G.G.Variables'!#REF!*[1]Histograma!K30 -> #REF! | P33: =+'G.G.Variables'!#REF!*[1]Histograma!L30 -> #REF! | Q33: =+'G.G.Variables'!#REF!*[1]Histograma!M30 -> #REF! | R33: =+'G.G.Variables'!#REF!*[1]Histograma!N30 -> #REF! | S33: =+'G.G.Variables'!#REF!*[1]Histograma!O30 -> #REF! | T33: =+'G.G.Variables'!#REF!*[1]Histograma!P30 -> #REF! | ... X33: =+'G.G.Variables'!#REF!*[1]Histograma!T30 -> #REF! | Z33: =+SUM(M33:X33) -> #REF!
C34: 1.02 | E34: REMUNERACIÓN PERSONAL ADMINISTRATIVO | F34: 378032.62 | K34: =+IF(#REF!="FORÁNEO",J34+1750,J34) -> #REF!
C35: 1.02.01 | E35: Administrador | F35: 148573.68 | J35: 6200 | K35: =+IF(#REF!="FORÁNEO",J35+1750,J35) -> #REF! | M35: =+#REF! -> #REF! | N35: =+#REF! -> #REF! | O35: =+#REF! -> #REF! | P35: =+#REF! -> #REF! | Q35: =+#REF! -> #REF! | R35: =+#REF! -> #REF! | S35: =+#REF! -> #REF! | T35: =+#REF! -> #REF! | U35: =+#REF!/2 -> #REF! | V35: =+#REF! -> #REF! | W35: =+#REF! -> #REF! | X35: =+W35/2 -> #REF! | Z35: =SUM(M35:X35) -> #REF!
C36: 1.02.02 | E36: Encargado de Logística | F36: 89219.82 | J36: 5500 | K36: =+IF(#REF!="FORÁNEO",J36+1750,J36) -> #REF! | M36: =+#REF! -> #REF! | N36: =+#REF! -> #REF! | O36: =+#REF! -> #REF! | P36: =+#REF! -> #REF! | Q36: =+#REF! -> #REF! | R36: =+#REF! -> #REF! | S36: =+#REF! -> #REF! | T36: =+#REF! -> #REF! | U36: =+#REF!/2 -> #REF! | V36: =+#REF! -> #REF! | W36: =+#REF! -> #REF! | X36: =+W36/2 -> #REF! | Z36: =SUM(M36:X36) -> #REF!
C37: 1.02.03 | E37: Almacenero | F37: 59084.24 | J37: 4200 | K37: =+IF(#REF!="FORÁNEO",J37+1750,J37) -> #REF! | M37: =+#REF! -> #REF! | N37: =+#REF! -> #REF! | O37: =+#REF! -> #REF! | P37: =+#REF! -> #REF! | Q37: =+#REF! -> #REF! | R37: =+#REF! -> #REF! | S37: =+#REF! -> #REF! | T37: =+#REF! -> #REF! | U37: =+#REF!/2 -> #REF! | V37: =+#REF! -> #REF! | Z37: =SUM(M37:X37) -> #REF!
C38: 1.02.04 | E38: Control Documentario (*) | F38: 81154.88 | J38: 5000 | K38: =+IF(#REF!="FORÁNEO",J38+1750,J38) -> #REF! | M38: =+#REF! -> #REF! | N38: =+#REF! -> #REF! | O38: =+#REF! -> #REF! | P38: =+#REF! -> #REF! | Q38: =+#REF! -> #REF! | R38: =+#REF! -> #REF! | S38: =+#REF! -> #REF! | T38: =+#REF! -> #REF! | U38: =+#REF!/2 -> #REF! | V38: =+#REF! -> #REF! | W38: =+#REF! -> #REF! | X38: =+W38/2 -> #REF! | Z38: =SUM(M38:X38) -> #REF!
C39: 1.03 | E39: REMUNERACIÓN PERSONAL AUXILIAR | F39: 142802.43 | K39: =+IF(#REF!="FORÁNEO",J39+1750,J39) -> #REF!
C40: 1.03.01 | E40: Auxiliar Almacenero | F40: 35700.61 | J40: 2500 | K40: =+IF(#REF!="FORÁNEO",J40+1750,J40) -> #REF! | M40: =+#REF! -> #REF! | N40: =+#REF! -> #REF! | O40: =+#REF! -> #REF! | P40: =+#REF! -> #REF! | Q40: =+#REF! -> #REF! | R40: =+#REF! -> #REF! | S40: =+#REF! -> #REF! | T40: =+#REF! -> #REF! | U40: =+#REF!/2 -> #REF! | V40: =+#REF! -> #REF! | Z40: =SUM(M40:X40) -> #REF!
C41: 1.03.02 | E41: Guardianes en Campamento y componente | F41: 107101.82 | J41: 2500 | K41: =+IF(#REF!="FORÁNEO",J41+1750,J41) -> #REF! | M41: =+#REF!*3 -> #REF! | N41: =+#REF!*3 -> #REF! | O41: =+#REF!*3 -> #REF! | P41: =+#REF!*3 -> #REF! | Q41: =+#REF!*3 -> #REF! | R41: =+#REF!*3 -> #REF! | S41: =+#REF!*3 -> #REF! | T41: =+#REF!*3 -> #REF! | U41: =+#REF!*3/2 -> #REF! | V41: =+#REF!*3 -> #REF! | Z41: =SUM(M41:X41) -> #REF!
C42: 2 | D42: PQ.08.602 | E42: CONSUMIBLES, EQUIPOS Y LICENCIAS NO INCLUIDOS EN LOS COSTOS DIRECTOS | F42: 112160 | K42: =+IF(#REF!="FORÁNEO",J42+1750,J42) -> #REF!
C43: 2.01 | E43: Radios de comunicación | F43: 15400 | J43: 700 | K43: =+IF(#REF!="FORÁNEO",J43+1750,J43) -> #REF! | M43: =+F43 -> 15400 | Z43: =SUM(M43:X43) -> 15400
C44: =+C43+0.01 -> 2.02 | E44: Equipos de Cómputo | F44: 66500 | J44: 350 | K44: =+IF(#REF!="FORÁNEO",J44+1750,J44) -> #REF! | M44: =+#REF!*#REF! -> #REF! | N44: =+#REF!*#REF! -> #REF! | O44: =+#REF!*#REF! -> #REF! | P44: =+#REF!*#REF! -> #REF! | Q44: =+#REF!*#REF! -> #REF! | R44: =+#REF!*#REF! -> #REF! | S44: =+#REF!*#REF! -> #REF! | T44: =+#REF!*#REF! -> #REF! | U44: =+#REF!*#REF! -> #REF! | V44: =+#REF!*#REF!/2 -> #REF! | Z44: =SUM(M44:X44) -> #REF!
E45: =+E44 -> Equipos de Cómputo | F45: 4900 | J45: 350 | K45: =+IF(#REF!="FORÁNEO",J45+1750,J45) -> #REF! | M45: =#REF!*2*[1]Histograma!I29 -> #REF! | N45: =#REF!*2*[1]Histograma!J29 -> #REF! | O45: =#REF!*2*[1]Histograma!K29 -> #REF! | P45: =#REF!*2*[1]Histograma!L29 -> #REF! | Q45: =#REF!*2*[1]Histograma!M29 -> #REF! | R45: =#REF!*2*[1]Histograma!N29 -> #REF! | S45: =#REF!*2*[1]Histograma!O29 -> #REF! | T45: =#REF!*2*[1]Histograma!P29 -> #REF! | ... V45: =#REF!*2*[1]Histograma!R29 -> #REF! | Z45: =SUM(M45:X45) -> #REF!
C46: =+C44+0.01 -> 2.03 | E46: Celulares | F46: 17100 | J46: 90 | K46: =+IF(#REF!="FORÁNEO",J46+1750,J46) -> #REF! | M46: =#REF!*#REF! -> #REF! | N46: =#REF!*#REF! -> #REF! | O46: =#REF!*#REF! -> #REF! | P46: =#REF!*#REF! -> #REF! | Q46: =#REF!*#REF! -> #REF! | R46: =#REF!*#REF! -> #REF! | S46: =#REF!*#REF! -> #REF! | T46: =#REF!*#REF! -> #REF! | U46: =#REF!*#REF! -> #REF! | V46: =#REF!*#REF!/2 -> #REF! | Z46: =SUM(M46:X46) -> #REF!
...

Sheet G.G.Fijos
E2: GASTOS GENERALES FIJOS DEL PAQUETE 08
E3: =+'[1]Res. G.G'!E3 -> “CONSTRUCCIÓN DEL SISTEMA DE DRENAJE URBANO EN EL SECTOR JESÚS MARÍA – CANAL Y OBRAS DE ESTABILIZACIÓN EN LAS LADERAS DEL SECTOR JESÚS MARÍA (PAQUETE 08)”
F4: =+'[1]Res. G.G'!K4 -> 45894
C6: ANÁLISIS DE GASTOS GENERALES FIJOS
C7: ='[1]Res. G.G'!E8 -> 9.5
C9: ITEM | D9: CUENTA COSTOS | E9: DESCRIPCION | F9: P. PARCIAL (S)
C10: 1 | D10: PQ.08.701 | E10: CONTRIBUCIÓN A SENCICO | F10: 71122.44
C11: =+C10+0.01 -> 1.01 | E11: SENCICO (0.2% del presupuesto sin IGV)
C14: TOTAL GASTOS GENERALES FIJOS | F14: =+#REF!+F10 -> #REF!
C17: Consideraciones:
C18: No se consideran costos corporativos, dado que estan cubiertos por la Utilidad.
C19: Los costos indicados son estimados, corresponden a los recursos mínimos en que incurre toda empresa en sus oficinas corporativas.

Sheet PPTO
A1: ÍTEM | B1: CUENTA COSTOS | C1: DESCRIPCIÓN | D1: UND. | E1: METRADO | F1: P.U (S/) | G1: P. PARCIAL (S)
A3: 01 | C3: OBRAS PROVISIONALES | G3: =SUM(G4:G10) -> 1938678.5
A4: 01.01 | B4: PQ.08.101 | C4: MOVILIZACION Y DESMOVILIZACION DE EQUIPOS Y/O MAQUINARIAS PAQ-8 | D4: glb | E4: 1 | F4: 520830 | G4: =ROUND(E4*F4,2) -> 520830
A5: 01.02 | B5: PQ.08.105 | C5: CARTEL DE IDENTIFICACION DE LA OBRA DE 3.60 X 2.40 M | D5: und | E5: 2 | F5: 3446.8 | G5: =ROUND(E5*F5,2) -> 6893.6
A6: 01.03 | B6: PQ.08.102 | C6: IMPLEMENTACIÓN DEL PLAN DE GESTION DE TRÁFICO VEHICULAR (PAQ-8) | D6: mes | E6: 11 | F6: 70700.15 | G6: =ROUND(E6*F6,2) -> 777701.65
A7: 01.04 | B7: PQ.08.103 | C7: PLAN DE SALUD, SEGURIDAD Y MEDIO AMBIENTE PAQ-8 | D7: glb | E7: 1 | F7: 326560.17 | G7: =ROUND(E7*F7,2) -> 326560.17
A8: 01.05 | B8: PQ.08.104 | C8: PLAN DE MANEJO AMBIENTAL PAQ-8 | D8: glb | E8: 1 | F8: 122241.55 | G8: =ROUND(E8*F8,2) -> 122241.55
A9: 01.06 | B9: PQ.08.105 | C9: PLAN DE CONTROL CONTRA EL COVID-19 PAQ-8 | D9: glb | E9: 1 | F9: 73343.62 | G9: =ROUND(E9*F9,2) -> 73343.62
A10: 01.07 | B10: PQ.08.105 | C10: PLAN DE MANEJO DE AGUAS PLUVIALES Y SUPERFICIALES (PAQ-08) | D10: glb | E10: 1 | F10: 111107.92 | G10: =ROUND(E10*F10,2) -> 111107.92
A11: 02 | C11: CAMPAMENTO DE OBRA - YALE 3 | G11: =SUM(G12:G35) -> 1250944.1
A12: 02.01 | B12: PQ.08.106 | C12: TRAZO Y REPLANTEO | D12: m2 | E12: 9490 | F12: 3.21 | G12: =ROUND(E12*F12,2) -> 30462.9
A13: 02.02 | B13: PQ.08.106 | C13: PERFILADO Y COMPACTADO PARA CAMPAMENTO | D13: m2 | E13: 9490 | F13: 6.45 | G13: =ROUND(E13*F13,2) -> 61210.5
A14: 02.03 | B14: PQ.08.106 | C14: TRANSPORTE DE MATERIAL GRANULAR, D<=1 KM | D14: m3-km | E14: 1898 | F14: 8.06 | G14: =ROUND(E14*F14,2) -> 15297.88
A15: 02.04 | B15: PQ.08.106 | C15: SUMINISTRO EN PUNTO DE ACOPIO DE MATERIAL DE PRÉSTAMO (AFIRMADO) | D15: m3 | E15: 1898 | F15: 78.24 | G15: =ROUND(E15*F15,2) -> 148499.52
A16: 02.05 | B16: PQ.08.106 | C16: CONFORMACIÓN DE TERRENO CON MATERIAL DE AFIRMADO | D16: m3 | E16: 1898 | F16: 16.49 | G16: =ROUND(E16*F16,2) -> 31298.02
A17: 02.06 | B17: PQ.08.106 | C17: CONFORMACION Y COMPACTACION CON MATERIAL PROPIO | D17: m3 | E17: 2035.2 | F17: 16.49 | G17: =ROUND(E17*F17,2) -> 33560.45
A18: 02.07 | B18: PQ.08.106 | C18: CERCO DE CAMPAMENTO | D18: m | E18: 396 | F18: 191.5 | G18: =ROUND(E18*F18,2) -> 75834
A19: 02.08 | B19: PQ.08.106 | C19: PORTON CAMPAMENTO | D19: und | E19: 1 | F19: 4250 | G19: =ROUND(E19*F19,2) -> 4250
A20: 02.09 | B20: PQ.08.106 | C20: GRUPO ELECTROGENO | D20: mes | E20: 11 | F20: 17879.42 | G20: =ROUND(E20*F20,2) -> 196673.62
A21: 02.10 | B21: PQ.08.106 | C21: SERVICIO DE INTERNET | D21: mes | E21: 11 | F21: 819.18 | G21: =ROUND(E21*F21,2) -> 9010.98
A22: 02.11 | B22: PQ.08.106 | C22: SERVICIO DE LIMPIEZA DE OFICINA | D22: mes | E22: 11 | F22: 3591.94 | G22: =ROUND(E22*F22,2) -> 39511.34
A23: 02.12 | B23: PQ.08.106 | C23: SERVICIO DE SEGURIDAD DE OFICINA | D23: mes | E23: 11 | F23: 12771.34 | G23: =ROUND(E23*F23,2) -> 140484.74
... A35: 02.24 | B35: PQ.08.106 | C35: AREA DE LABORATORIO DE SUELOS, PAVIMENTOS Y CONCRETO | D35: m2 | E35: 35 | F35: 556.31 | G35: =ROUND(E35*F35,2) -> 19470.85
A36: 03 | C36: HABILITACION DE PUNTO DE ACOPIO - YALE 3 | G36: =SUM(G37:G43) -> 525541.31
A37: 03.01 | B37: PQ.08.107 | C37: TRAZO Y REPLANTEO | D37: m2 | E37: 17160 | F37: 3.21 | G37: =ROUND(E37*F37,2) -> 55083.6
A38: 03.02 | B38: PQ.08.107 | C38: PERFILADO Y COMPACTADO PARA PUNTO DE ACOPIO | D38: m2 | E38: 17160 | F38: 3.65 | G38: =ROUND(E38*F38,2) -> 62634
A39: 03.03 | B39: PQ.08.107 | C39: SUMINISTRO EN PUNTO DE ACOPIO DE MATERIAL DE PRÉSTAMO (AFIRMADO) | D39: m3 | E39: 3432 | F39: 78.24 | G39: =ROUND(E39*F39,2) -> 268519.68
A40: 03.04 | B40: PQ.08.107 | C40: CONFORMACIÓN DE TERRENO CON MATERIAL DE AFIRMADO | D40: m3 | E40: 3432 | F40: 16.49 | G40: =ROUND(E40*F40,2) -> 56593.68
A41: 03.05 | B41: PQ.08.107 | C41: CERCO PARA PUNTO DE ACOPIO | D41: m | E41: 384 | F41: 191.5 | G41: =ROUND(E41*F41,2) -> 73536
A42: 03.06 | B42: PQ.08.107 | C42: PORTON PUNTO DE ACOPIO | D42: und | E42: 1 | F42: 4250 | G42: =ROUND(E42*F42,2) -> 4250
A43: 03.07 | B43: PQ.08.107 | C43: CASETA DE GUARDIANÍA | D43: mes | E43: 9 | F43: 547.15 | G43: =ROUND(E43*F43,2) -> 4924.35
A44: 04 | C44: ACCESO A COMPONENTE 4 - CANAL JESUS MARIA | G44: =G45+G57+G69 -> 1633038.2
A45: 04.01 | C45: ACCESO 01 | G45: =SUM(G46:G56) -> 1409109.5
A46: 04.01.01 | B46: PQ.08.108 | C46: TRAZO Y REPLANTEO PARA OBRAS VIALES | D46: km | E46: 1.31 | F46: 1893.96 | G46: =ROUND(E46*F46,2) -> 2481.09
A47: 04.01.02 | B47: PQ.08.108 | C47: EXCAVACION C/MAQ. EN TERRENO NORMAL H<=2M | D47: m3 | E47: 13890.8 | F47: 49.92 | G47: =ROUND(E47*F47,2) -> 693428.74
A48: 04.01.03 | B48: PQ.08.108 | C48: ACARREO DE MATERIAL PROVENIENTE DE EXCAVACIONES, D<= 1KM | D48: m3-km | E48: 13890.8 | F48: 8.06 | G48: =ROUND(E48*F48,2) -> 111959.85
A49: 04.01.04 | B49: PQ.08.108 | C49: RELLENO COMPACTADO CON MATERIAL PROPIO | D49: m3 | E49: 4794.07 | F49: 26.25 | G49: =ROUND(E49*F49,2) -> 125844.34
A50: 04.01.05 | B50: PQ.08.108 | C50: PERFILADO Y COMPACTADO EN ZONAS DE CORTE | D50: m2 | E50: 7680 | F50: 1.95 | G50: =ROUND(E50*F50,2) -> 14976
A51: 04.01.06 | B51: PQ.08.108 | C51: CONFORMACION DE TERRENO CON MATERIAL DE AFIRMADO (E=0.20M) | D51: m3 | E51: 1803.84 | F51: 25.82 | G51: =ROUND(E51*F51,2) -> 46575.15
A52: 04.01.07 | B52: PQ.08.108 | C52: SUMINISTRO EN PUNTO DE ACOPIO DE MATERIAL DE PRESTAMO (AFIRMADO) | D52: m3 | E52: 1803.84 | F52: 78.24 | G52: =ROUND(E52*F52,2) -> 141132.44
...

Sheet CAOP
C2: CALENDARIO DE AVANCE DE OBRA PORCENTUAL DEL PAQUETE 08
C4: “CONSTRUCCIÓN DEL SISTEMA DE DRENAJE URBANO EN EL SECTOR JESÚS MARÍA – CANAL Y OBRAS DE ESTABILIZACIÓN EN LAS LADERAS DEL SECTOR JESÚS MARÍA (PAQUETE 08)”
B7: =+C2 -> CALENDARIO DE AVANCE DE OBRA PORCENTUAL DEL PAQUETE 08
B8: ÍTEM | C8: DESCRIPCIÓN | D8: 1 | E8: 2 | F8: 3 | G8: 4 | H8: 5 | I8: 6 | J8: 7 | K8: 8 | L8: 9 | M8: 10 | N8: TOTAL
D9: (S/) | E9: (S/) | F9: (S/) | G9: (S/) | H9: (S/) | I9: (S/) | J9: (S/) | K9: (S/) | L9: (S/) | M9: (S/)
B10: 01 | C10: OBRAS PROVISIONALES | D10: =PPTO!#REF!/PPTO!G3 -> #REF! | E10: =PPTO!#REF!/PPTO!G3 -> #REF! | F10: =PPTO!#REF!/PPTO!G3 -> #REF! | G10: =PPTO!#REF!/PPTO!G3 -> #REF! | H10: =PPTO!#REF!/PPTO!G3 -> #REF! | I10: =PPTO!#REF!/PPTO!G3 -> #REF! | J10: =PPTO!#REF!/PPTO!G3 -> #REF! | K10: =PPTO!#REF!/PPTO!G3 -> #REF! | L10: =PPTO!#REF!/PPTO!G3 -> #REF! | M10: =PPTO!#REF!/PPTO!G3 -> #REF! | N10: =SUM(D10:M10) -> #REF!
B11: 01.01 | C11: MOVILIZACION Y DESMOVILIZACION DE EQUIPOS Y/O MAQUINARIAS PAQ-8 | D11: =PPTO!#REF!/PPTO!G4 -> #REF! | E11: =PPTO!#REF!/PPTO!G4 -> #REF! | F11: =PPTO!#REF!/PPTO!G4 -> #REF! | G11: =PPTO!#REF!/PPTO!G4 -> #REF! | H11: =PPTO!#REF!/PPTO!G4 -> #REF! | I11: =PPTO!#REF!/PPTO!G4 -> #REF! | J11: =PPTO!#REF!/PPTO!G4 -> #REF! | K11: =PPTO!#REF!/PPTO!G4 -> #REF! | L11: =PPTO!#REF!/PPTO!G4 -> #REF! | M11: =PPTO!#REF!/PPTO!G4 -> #REF! | N11: =SUM(D11:M11) -> #REF!
B12: 01.02 | C12: CARTEL DE IDENTIFICACION DE LA OBRA DE 3.60 X 2.40 M | D12: =PPTO!#REF!/PPTO!G5 -> #REF! | E12: =PPTO!#REF!/PPTO!G5 -> #REF! | F12: =PPTO!#REF!/PPTO!G5 -> #REF! | G12: =PPTO!#REF!/PPTO!G5 -> #REF! | H12: =PPTO!#REF!/PPTO!G5 -> #REF! | I12: =PPTO!#REF!/PPTO!G5 -> #REF! | J12: =PPTO!#REF!/PPTO!G5 -> #REF! | K12: =PPTO!#REF!/PPTO!G5 -> #REF! | L12: =PPTO!#REF!/PPTO!G5 -> #REF! | M12: =PPTO!#REF!/PPTO!G5 -> #REF! | N12: =SUM(D12:M12) -> #REF!
B13: 01.03 | C13: IMPLEMENTACIÓN DEL PLAN DE GESTION DE TRÁFICO VEHICULAR (PAQ-8) | D13: =PPTO!#REF!/PPTO!G6 -> #REF! | E13: =PPTO!#REF!/PPTO!G6 -> #REF! | F13: =PPTO!#REF!/PPTO!G6 -> #REF! | G13: =PPTO!#REF!/PPTO!G6 -> #REF! | H13: =PPTO!#REF!/PPTO!G6 -> #REF! | I13: =PPTO!#REF!/PPTO!G6 -> #REF! | J13: =PPTO!#REF!/PPTO!G6 -> #REF! | K13: =PPTO!#REF!/PPTO!G6 -> #REF! | L13: =PPTO!#REF!/PPTO!G6 -> #REF! | M13: =PPTO!#REF!/PPTO!G6 -> #REF! | N13: =SUM(D13:M13) -> #REF!
B14: 01.04 | C14: PLAN DE SALUD, SEGURIDAD Y MEDIO AMBIENTE PAQ-8 | D14: =PPTO!#REF!/PPTO!G7 -> #REF! | E14: =PPTO!#REF!/PPTO!G7 -> #REF! | F14: =PPTO!#REF!/PPTO!G7 -> #REF! | G14: =PPTO!#REF!/PPTO!G7 -> #REF! | H14: =PPTO!#REF!/PPTO!G7 -> #REF! | I14: =PPTO!#REF!/PPTO!G7 -> #REF! | J14: =PPTO!#REF!/PPTO!G7 -> #REF! | K14: =PPTO!#REF!/PPTO!G7 -> #REF! | L14: =PPTO!#REF!/PPTO!G7 -> #REF! | M14: =PPTO!#REF!/PPTO!G7 -> #REF! | N14: =SUM(D14:M14) -> #REF!
B15: 01.05 | C15: PLAN DE MANEJO AMBIENTAL PAQ-8 | D15: =PPTO!#REF!/PPTO!G8 -> #REF! | E15: =PPTO!#REF!/PPTO!G8 -> #REF! | F15: =PPTO!#REF!/PPTO!G8 -> #REF! | G15: =PPTO!#REF!/PPTO!G8 -> #REF! | H15: =PPTO!#REF!/PPTO!G8 -> #REF! | I15: =PPTO!#REF!/PPTO!G8 -> #REF! | J15: =PPTO!#REF!/PPTO!G8 -> #REF! | K15: =PPTO!#REF!/PPTO!G8 -> #REF! | L15: =PPTO!#REF!/PPTO!G8 -> #REF! | M15: =PPTO!#REF!/PPTO!G8 -> #REF! | N15: =SUM(D15:M15) -> #REF!
B16: 01.06 | C16: PLAN DE CONTROL CONTRA EL COVID-19 PAQ-8 | D16: =PPTO!#REF!/PPTO!G9 -> #REF! | E16: =PPTO!#REF!/PPTO!G9 -> #REF! | F16: =PPTO!#REF!/PPTO!G9 -> #REF! | G16: =PPTO!#REF!/PPTO!G9 -> #REF! | H16: =PPTO!#REF!/PPTO!G9 -> #REF! | I16: =PPTO!#REF!/PPTO!G9 -> #REF! | J16: =PPTO!#REF!/PPTO!G9 -> #REF! | K16: =PPTO!#REF!/PPTO!G9 -> #REF! | L16: =PPTO!#REF!/PPTO!G9 -> #REF! | M16: =PPTO!#REF!/PPTO!G9 -> #REF! | N16: =SUM(D16:M16) -> #REF!
B17: 01.07 | C17: PLAN DE MANEJO DE AGUAS PLUVIALES Y SUPERFICIALES (PAQ-08) | D17: =PPTO!#REF!/PPTO!G10 -> #REF! | E17: =PPTO!#REF!/PPTO!G10 -> #REF! | F17: =PPTO!#REF!/PPTO!G10 -> #REF! | G17: =PPTO!#REF!/PPTO!G10 -> #REF! | H17: =PPTO!#REF!/PPTO!G10 -> #REF! | I17: =PPTO!#REF!/PPTO!G10 -> #REF! | J17: =PPTO!#REF!/PPTO!G10 -> #REF! | K17: =PPTO!#REF!/PPTO!G10 -> #REF! | L17: =PPTO!#REF!/PPTO!G10 -> #REF! | M17: =PPTO!#REF!/PPTO!G10 -> #REF! | N17: =SUM(D17:M17) -> #REF!
B18: 02 | C18: CAMPAMENTO DE OBRA - YALE 3 | D18: =PPTO!#REF!/PPTO!G11 -> #REF! | E18: =PPTO!#REF!/PPTO!G11 -> #REF! | F18: =PPTO!#REF!/PPTO!G11 -> #REF! | G18: =PPTO!#REF!/PPTO!G11 -> #REF! | H18: =PPTO!#REF!/PPTO!G11 -> #REF! | I18: =PPTO!#REF!/PPTO!G11 -> #REF! | J18: =PPTO!#REF!/PPTO!G11 -> #REF! | K18: =PPTO!#REF!/PPTO!G11 -> #REF! | L18: =PPTO!#REF!/PPTO!G11 -> #REF! | M18: =PPTO!#REF!/PPTO!G11 -> #REF! | N18: =SUM(D18:M18) -> #REF!
B19: 02.01 | C19: TRAZO Y REPLANTEO | D19: =PPTO!#REF!/PPTO!G12 -> #REF! | E19: =PPTO!#REF!/PPTO!G12 -> #REF! | F19: =PPTO!#REF!/PPTO!G12 -> #REF! | G19: =PPTO!#REF!/PPTO!G12 -> #REF! | H19: =PPTO!#REF!/PPTO!G12 -> #REF! | I19: =PPTO!#REF!/PPTO!G12 -> #REF! | J19: =PPTO!#REF!/PPTO!G12 -> #REF! | K19: =PPTO!#REF!/PPTO!G12 -> #REF! | L19: =PPTO!#REF!/PPTO!G12 -> #REF! | M19: =PPTO!#REF!/PPTO!G12 -> #REF! | N19: =SUM(D19:M19) -> #REF!
B20: 02.02 | C20: PERFILADO Y COMPACTADO PARA CAMPAMENTO | D20: =PPTO!#REF!/PPTO!G13 -> #REF! | E20: =PPTO!#REF!/PPTO!G13 -> #REF! | F20: =PPTO!#REF!/PPTO!G13 -> #REF! | G20: =PPTO!#REF!/PPTO!G13 -> #REF! | H20: =PPTO!#REF!/PPTO!G13 -> #REF! | I20: =PPTO!#REF!/PPTO!G13 -> #REF! | J20: =PPTO!#REF!/PPTO!G13 -> #REF! | K20: =PPTO!#REF!/PPTO!G13 -> #REF! | L20: =PPTO!#REF!/PPTO!G13 -> #REF! | M20: =PPTO!#REF!/PPTO!G13 -> #REF! | N20: =SUM(D20:M20) -> #REF!
B21: 02.03 | C21: TRANSPORTE DE MATERIAL GRANULAR, D<=1 KM | D21: =PPTO!#REF!/PPTO!G14 -> #REF! | E21: =PPTO!#REF!/PPTO!G14 -> #REF! | F21: =PPTO!#REF!/PPTO!G14 -> #REF! | G21: =PPTO!#REF!/PPTO!G14 -> #REF! | H21: =PPTO!#REF!/PPTO!G14 -> #REF! | I21: =PPTO!#REF!/PPTO!G14 -> #REF! | J21: =PPTO!#REF!/PPTO!G14 -> #REF! | K21: =PPTO!#REF!/PPTO!G14 -> #REF! | L21: =PPTO!#REF!/PPTO!G14 -> #REF! | M21: =PPTO!#REF!/PPTO!G14 -> #REF! | N21: =SUM(D21:M21) -> #REF!
... B1507: 07.02.01.01 | C1507: DISPOSICIÓN Y CONFORMACIÓN DEL MATERIAL EXCEDENTE (DME) | D1507: =PPTO!#REF!/PPTO!G1500 -> #REF! | E1507: =PPTO!#REF!/PPTO!G1500 -> #REF! | F1507: =PPTO!#REF!/PPTO!G1500 -> #REF! | G1507: =PPTO!#REF!/PPTO!G1500 -> #REF! | H1507: =PPTO!#REF!/PPTO!G1500 -> #REF! | I1507: =PPTO!#REF!/PPTO!G1500 -> #REF! | J1507: =PPTO!#REF!/PPTO!G1500 -> #REF! | K1507: =PPTO!#REF!/PPTO!G1500 -> #REF! | L1507: =PPTO!#REF!/PPTO!G1500 -> #REF! | M1507: =PPTO!#REF!/PPTO!G1500 -> #REF! | N1507: =SUM(D1507:M1507) -> #REF!

Sheet CAOF
C2: CALENDARIO DE AVANCE DE OBRA FISICO DEL PAQUETE 08
C4: “CONSTRUCCIÓN DEL SISTEMA DE DRENAJE URBANO EN EL SECTOR JESÚS MARÍA – CANAL Y OBRAS DE ESTABILIZACIÓN EN LAS LADERAS DEL SECTOR JESÚS MARÍA (PAQUETE 08)”
B7: =+C2 -> CALENDARIO DE AVANCE DE OBRA FISICO DEL PAQUETE 08
B8: ÍTEM | C8: DESCRIPCIÓN | D8: UND. | E8: METRADO | F8: 1 | G8: 2 | H8: 3 | I8: 4 | J8: 5 | K8: 6 | L8: 7 | M8: 8 | N8: 9 | O8: 10
F9: (S/) | G9: (S/) | H9: (S/) | I9: (S/) | J9: (S/) | K9: (S/) | L9: (S/) | M9: (S/) | N9: (S/) | O9: (S/)
B10: 01 | C10: OBRAS PROVISIONALES | Q10: =SUM(F10:O10) -> 0 | R10: =E10-Q10 -> 0
B11: 01.01 | C11: MOVILIZACION Y DESMOVILIZACION DE EQUIPOS Y/O MAQUINARIAS PAQ-8 | D11: glb | E11: 1 | F11: =E11*CAOP!D11 -> #REF! | G11: =E11*CAOP!E11 -> #REF! | H11: =E11*CAOP!F11 -> #REF! | I11: =E11*CAOP!G11 -> #REF! | J11: =E11*CAOP!H11 -> #REF! | K11: =E11*CAOP!I11 -> #REF! | L11: =E11*CAOP!J11 -> #REF! | M11: =E11*CAOP!K11 -> #REF! | N11: =E11*CAOP!L11 -> #REF! | O11: =E11*CAOP!M11 -> #REF! | Q11: =SUM(F11:O11) -> #REF! | R11: =E11-Q11 -> #REF!
B12: 01.02 | C12: CARTEL DE IDENTIFICACION DE LA OBRA DE 3.60 X 2.40 M | D12: und | E12: 2 | F12: =E12*CAOP!D12 -> #REF! | G12: =E12*CAOP!E12 -> #REF! | H12: =E12*CAOP!F12 -> #REF! | I12: =E12*CAOP!G12 -> #REF! | J12: =E12*CAOP!H12 -> #REF! | K12: =E12*CAOP!I12 -> #REF! | L12: =E12*CAOP!J12 -> #REF! | M12: =E12*CAOP!K12 -> #REF! | N12: =E12*CAOP!L12 -> #REF! | O12: =E12*CAOP!M12 -> #REF! | Q12: =SUM(F12:O12) -> #REF! | R12: =E12-Q12 -> #REF!
B13: 01.03 | C13: IMPLEMENTACIÓN DEL PLAN DE GESTION DE TRÁFICO VEHICULAR (PAQ-8) | D13: mes | E13: 11 | F13: =E13*CAOP!D13 -> #REF! | G13: =E13*CAOP!E13 -> #REF! | H13: =E13*CAOP!F13 -> #REF! | I13: =E13*CAOP!G13 -> #REF! | J13: =E13*CAOP!H13 -> #REF! | K13: =E13*CAOP!I13 -> #REF! | L13: =E13*CAOP!J13 -> #REF! | M13: =E13*CAOP!K13 -> #REF! | N13: =E13*CAOP!L13 -> #REF! | O13: =E13*CAOP!M13 -> #REF! | Q13: =SUM(F13:O13) -> #REF! | R13: =E13-Q13 -> #REF!
B14: 01.04 | C14: PLAN DE SALUD, SEGURIDAD Y MEDIO AMBIENTE PAQ-8 | D14: glb | E14: 1 | F14: =E14*CAOP!D14 -> #REF! | G14: =E14*CAOP!E14 -> #REF! | H14: =E14*CAOP!F14 -> #REF! | I14: =E14*CAOP!G14 -> #REF! | J14: =E14*CAOP!H14 -> #REF! | K14: =E14*CAOP!I14 -> #REF! | L14: =E14*CAOP!J14 -> #REF! | M14: =E14*CAOP!K14 -> #REF! | N14: =E14*CAOP!L14 -> #REF! | O14: =E14*CAOP!M14 -> #REF! | Q14: =SUM(F14:O14) -> #REF! | R14: =E14-Q14 -> #REF!
B15: 01.05 | C15: PLAN DE MANEJO AMBIENTAL PAQ-8 | D15: glb | E15: 1 | F15: =E15*CAOP!D15 -> #REF! | G15: =E15*CAOP!E15 -> #REF! | H15: =E15*CAOP!F15 -> #REF! | I15: =E15*CAOP!G15 -> #REF! | J15: =E15*CAOP!H15 -> #REF! | K15: =E15*CAOP!I15 -> #REF! | L15: =E15*CAOP!J15 -> #REF! | M15: =E15*CAOP!K15 -> #REF! | N15: =E15*CAOP!L15 -> #REF! | O15: =E15*CAOP!M15 -> #REF! | Q15: =SUM(F15:O15) -> #REF! | R15: =E15-Q15 -> #REF!
B16: 01.06 | C16: PLAN DE CONTROL CONTRA EL COVID-19 PAQ-8 | D16: glb | E16: 1 | F16: =E16*CAOP!D16 -> #REF! | G16: =E16*CAOP!E16 -> #REF! | H16: =E16*CAOP!F16 -> #REF! | I16: =E16*CAOP!G16 -> #REF! | J16: =E16*CAOP!H16 -> #REF! | K16: =E16*CAOP!I16 -> #REF! | L16: =E16*CAOP!J16 -> #REF! | M16: =E16*CAOP!K16 -> #REF! | N16: =E16*CAOP!L16 -> #REF! | O16: =E16*CAOP!M16 -> #REF! | Q16: =SUM(F16:O16) -> #REF! | R16: =E16-Q16 -> #REF!
B17: 01.07 | C17: PLAN DE MANEJO DE AGUAS PLUVIALES Y SUPERFICIALES (PAQ-08) | D17: glb | E17: 1 | F17: =E17*CAOP!D17 -> #REF! | G17: =E17*CAOP!E17 -> #REF! | H17: =E17*CAOP!F17 -> #REF! | I17: =E17*CAOP!G17 -> #REF! | J17: =E17*CAOP!H17 -> #REF! | K17: =E17*CAOP!I17 -> #REF! | L17: =E17*CAOP!J17 -> #REF! | M17: =E17*CAOP!K17 -> #REF! | N17: =E17*CAOP!L17 -> #REF! | O17: =E17*CAOP!M17 -> #REF! | Q17: =SUM(F17:O17) -> #REF! | R17: =E17-Q17 -> #REF!
B18: 02 | C18: CAMPAMENTO DE OBRA - YALE 3 | Q18: =SUM(F18:O18) -> 0 | R18: =E18-Q18 -> 0
B19: 02.01 | C19: TRAZO Y REPLANTEO | D19: m2 | E19: 9490 | F19: =E19*CAOP!D19 -> #REF! | G19: =E19*CAOP!E19 -> #REF! | H19: =E19*CAOP!F19 -> #REF! | I19: =E19*CAOP!G19 -> #REF! | J19: =E19*CAOP!H19 -> #REF! | K19: =E19*CAOP!I19 -> #REF! | L19: =E19*CAOP!J19 -> #REF! | M19: =E19*CAOP!K19 -> #REF! | N19: =E19*CAOP!L19 -> #REF! | O19: =E19*CAOP!M19 -> #REF! | Q19: =SUM(F19:O19) -> #REF! | R19: =E19-Q19 -> #REF!
B20: 02.02 | C20: PERFILADO Y COMPACTADO PARA CAMPAMENTO | D20: m2 | E20: 9490 | F20: =E20*CAOP!D20 -> #REF! | G20: =E20*CAOP!E20 -> #REF! | H20: =E20*CAOP!F20 -> #REF! | I20: =E20*CAOP!G20 -> #REF! | J20: =E20*CAOP!H20 -> #REF! | K20: =E20*CAOP!I20 -> #REF! | L20: =E20*CAOP!J20 -> #REF! | M20: =E20*CAOP!K20 -> #REF! | N20: =E20*CAOP!L20 -> #REF! | O20: =E20*CAOP!M20 -> #REF! | Q20: =SUM(F20:O20) -> #REF! | R20: =E20-Q20 -> #REF!
B21: 02.03 | C21: TRANSPORTE DE MATERIAL GRANULAR, D<=1 KM | D21: m3-km | E21: 1898 | F21: =E21*CAOP!D21 -> #REF! | G21: =E21*CAOP!E21 -> #REF! | H21: =E21*CAOP!F21 -> #REF! | I21: =E21*CAOP!G21 -> #REF! | J21: =E21*CAOP!H21 -> #REF! | K21: =E21*CAOP!I21 -> #REF! | L21: =E21*CAOP!J21 -> #REF! | M21: =E21*CAOP!K21 -> #REF! | N21: =E21*CAOP!L21 -> #REF! | O21: =E21*CAOP!M21 -> #REF! | Q21: =SUM(F21:O21) -> #REF! | R21: =E21-Q21 -> #REF!
B22: 02.04 | C22: SUMINISTRO EN PUNTO DE ACOPIO DE MATERIAL DE PRÉSTAMO (AFIRMADO) | D22: m3 | E22: 1898 | F22: =E22*CAOP!D22 -> #REF! | G22: =E22*CAOP!E22 -> #REF! | H22: =E22*CAOP!F22 -> #REF! | I22: =E22*CAOP!G22 -> #REF! | J22: =E22*CAOP!H22 -> #REF! | K22: =E22*CAOP!I22 -> #REF! | L22: =E22*CAOP!J22 -> #REF! | M22: =E22*CAOP!K22 -> #REF! | N22: =E22*CAOP!L22 -> #REF! | O22: =E22*CAOP!M22 -> #REF! | Q22: =SUM(F22:O22) -> #REF! | R22: =E22-Q22 -> #REF!
B23: 02.05 | C23: CONFORMACIÓN DE TERRENO CON MATERIAL DE AFIRMADO | D23: m3 | E23: 1898 | F23: =E23*CAOP!D23 -> #REF! | G23: =E23*CAOP!E23 -> #REF! | H23: =E23*CAOP!F23 -> #REF! | I23: =E23*CAOP!G23 -> #REF! | J23: =E23*CAOP!H23 -> #REF! | K23: =E23*CAOP!I23 -> #REF! | L23: =E23*CAOP!J23 -> #REF! | M23: =E23*CAOP!K23 -> #REF! | N23: =E23*CAOP!L23 -> #REF! | O23: =E23*CAOP!M23 -> #REF! | Q23: =SUM(F23:O23) -> #REF! | R23: =E23-Q23 -> #REF!
B24: 02.06 | C24: CONFORMACION Y COMPACTACION CON MATERAIL PROPIO | D24: m3 | E24: 2035.2 | F24: =E24*CAOP!D24 -> #REF! | G24: =E24*CAOP!E24 -> #REF! | H24: =E24*CAOP!F24 -> #REF! | I24: =E24*CAOP!G24 -> #REF! | J24: =E24*CAOP!H24 -> #REF! | K24: =E24*CAOP!I24 -> #REF! | L24: =E24*CAOP!J24 -> #REF! | M24: =E24*CAOP!K24 -> #REF! | N24: =E24*CAOP!L24 -> #REF! | O24: =E24*CAOP!M24 -> #REF! | Q24: =SUM(F24:O24) -> #REF! | R24: =E24-Q24 -> #REF!
B25: 02.07 | C25: CERCO DE CAMPAMENTO | D25: m | E25: 396 | F25: =E25*CAOP!D25 -> #REF! | G25: =E25*CAOP!E25 -> #REF! | H25: =E25*CAOP!F25 -> #REF! | I25: =E25*CAOP!G25 -> #REF! | J25: =E25*CAOP!H25 -> #REF! | K25: =E25*CAOP!I25 -> #REF! | L25: =E25*CAOP!J25 -> #REF! | M25: =E25*CAOP!K25 -> #REF! | N25: =E25*CAOP!L25 -> #REF! | O25: =E25*CAOP!M25 -> #REF! | Q25: =SUM(F25:O25) -> #REF! | R25: =E25-Q25 -> #REF!
B26: 02.08 | C26: PORTON CAMPAMENTO | D26: und | E26: 1 | F26: =E26*CAOP!D26 -> #REF! | G26: =E26*CAOP!E26 -> #REF! | H26: =E26*CAOP!F26 -> #REF! | I26: =E26*CAOP!G26 -> #REF! | J26: =E26*CAOP!H26 -> #REF! | K26: =E26*CAOP!I26 -> #REF! | L26: =E26*CAOP!J26 -> #REF! | M26: =E26*CAOP!K26 -> #REF! | N26: =E26*CAOP!L26 -> #REF! | O26: =E26*CAOP!M26 -> #REF! | Q26: =SUM(F26:O26) -> #REF! | R26: =E26-Q26 -> #REF!
B27: 02.09 | C27: GRUPO ELECTROGENO | D27: mes | E27: 11 | F27: =E27*CAOP!D27 -> #REF! | G27: =E27*CAOP!E27 -> #REF! | H27: =E27*CAOP!F27 -> #REF! | I27: =E27*CAOP!G27 -> #REF! | J27: =E27*CAOP!H27 -> #REF! | K27: =E27*CAOP!I27 -> #REF! | L27: =E27*CAOP!J27 -> #REF! | M27: =E27*CAOP!K27 -> #REF! | N27: =E27*CAOP!L27 -> #REF! | O27: =E27*CAOP!M27 -> #REF! | Q27: =SUM(F27:O27) -> #REF! | R27: =E27-Q27 -> #REF!
B28: 02.10 | C28: SERVICIO DE INTERNET | D28: mes | E28: 11 | F28: =E28*CAOP!D28 -> #REF! | G28: =E28*CAOP!E28 -> #REF! | H28: =E28*CAOP!F28 -> #REF! | I28: =E28*CAOP!G28 -> #REF! | J28: =E28*CAOP!H28 -> #REF! | K28: =E28*CAOP!I28 -> #REF! | L28: =E28*CAOP!J28 -> #REF! | M28: =E28*CAOP!K28 -> #REF! | N28: =E28*CAOP!L28 -> #REF! | O28: =E28*CAOP!M28 -> #REF! | Q28: =SUM(F28:O28) -> #REF! | R28: =E28-Q28 -> #REF!
B29: 02.11 | C29: SERVICIO DE LIMPIEZA DE OFICINA | D29: mes | E29: 11 | F29: =E29*CAOP!D29 -> #REF! | G29: =E29*CAOP!E29 -> #REF! | H29: =E29*CAOP!F29 -> #REF! | I29: =E29*CAOP!G29 -> #REF! | J29: =E29*CAOP!H29 -> #REF! | K29: =E29*CAOP!I29 -> #REF! | L29: =E29*CAOP!J29 -> #REF! | M29: =E29*CAOP!K29 -> #REF! | N29: =E29*CAOP!L29 -> #REF! | O29: =E29*CAOP!M29 -> #REF! | Q29: =SUM(F29:O29) -> #REF! | R29: =E29-Q29 -> #REF!
B30: 02.12 | C30: SERVICIO DE SEGURIDAD DE OFICINA | D30: mes | E30: 11 | F30: =E30*CAOP!D30 -> #REF! | G30: =E30*CAOP!E30 -> #REF! | H30: =E30*CAOP!F30 -> #REF! | I30: =E30*CAOP!G30 -> #REF! | J30: =E30*CAOP!H30 -> #REF! | K30: =E30*CAOP!I30 -> #REF! | L30: =E30*CAOP!J30 -> #REF! | M30: =E30*CAOP!K30 -> #REF! | N30: =E30*CAOP!L30 -> #REF! | O30: =E30*CAOP!M30 -> #REF! | Q30: =SUM(F30:O30) -> #REF! | R30: =E30-Q30 -> #REF!
... B42: 02.24 | C42: AREA DE LABORATORIO DE SUELOS, PAVIMENTOS Y CONCRETO | D42: m2 | E42: 35 | F42: =E42*CAOP!D42 -> #REF! | G42: =E42*CAOP!E42 -> #REF! | H42: =E42*CAOP!F42 -> #REF! | I42: =E42*CAOP!G42 -> #REF! | J42: =E42*CAOP!H42 -> #REF! | K42: =E42*CAOP!I42 -> #REF! | L42: =E42*CAOP!J42 -> #REF! | M42: =E42*CAOP!K42 -> #REF! | N42: =E42*CAOP!L42 -> #REF! | O42: =E42*CAOP!M42 -> #REF! | Q42: =SUM(F42:O42) -> #REF! | R42: =E42-Q42 -> #REF!
B43: 03 | C43: HABILITACION DE PUNTO DE ACOPIO - YALE 3 | Q43: =SUM(F43:O43) -> 0 | R43: =E43-Q43 -> 0
B44: 03.01 | C44: TRAZO Y REPLANTEO | D44: m2 | E44: 17160 | F44: =E44*CAOP!D44 -> #REF! | G44: =E44*CAOP!E44 -> #REF! | H44: =E44*CAOP!F44 -> #REF! | I44: =E44*CAOP!G44 -> #REF! | J44: =E44*CAOP!H44 -> #REF! | K44: =E44*CAOP!I44 -> #REF! | L44: =E44*CAOP!J44 -> #REF! | M44: =E44*CAOP!K44 -> #REF! | N44: =E44*CAOP!L44 -> #REF! | O44: =E44*CAOP!M44 -> #REF! | Q44: =SUM(F44:O44) -> #REF! | R44: =E44-Q44 -> #REF!
B45: 03.02 | C45: PERFILADO Y COMPACTADO PARA PUNTO DE ACOPIO | D45: m2 | E45: 17160 | F45: =E45*CAOP!D45 -> #REF! | G45: =E45*CAOP!E45 -> #REF! | H45: =E45*CAOP!F45 -> #REF! | I45: =E45*CAOP!G45 -> #REF! | J45: =E45*CAOP!H45 -> #REF! | K45: =E45*CAOP!I45 -> #REF! | L45: =E45*CAOP!J45 -> #REF! | M45: =E45*CAOP!K45 -> #REF! | N45: =E45*CAOP!L45 -> #REF! | O45: =E45*CAOP!M45 -> #REF! | Q45: =SUM(F45:O45) -> #REF! | R45: =E45-Q45 -> #REF!
B46: 03.03 | C46: SUMINISTRO EN PUNTO DE ACOPIO DE MATERIAL DE PRÉSTAMO (AFIRMADO) | D46: m3 | E46: 3432 | F46: =E46*CAOP!D46 -> #REF! | G46: =E46*CAOP!E46 -> #REF! | H46: =E46*CAOP!F46 -> #REF! | I46: =E46*CAOP!G46 -> #REF! | J46: =E46*CAOP!H46 -> #REF! | K46: =E46*CAOP!I46 -> #REF! | L46: =E46*CAOP!J46 -> #REF! | M46: =E46*CAOP!K46 -> #REF! | N46: =E46*CAOP!L46 -> #REF! | O46: =E46*CAOP!M46 -> #REF! | Q46: =SUM(F46:O46) -> #REF! | R46: =E46-Q46 -> #REF!
B47: 03.04 | C47: CONFORMACIÓN DE TERRENO CON MATERIAL DE AFIRMADO | D47: m3 | E47: 3432 | F47: =E47*CAOP!D47 -> #REF! | G47: =E47*CAOP!E47 -> #REF! | H47: =E47*CAOP!F47 -> #REF! | I47: =E47*CAOP!G47 -> #REF! | J47: =E47*CAOP!H47 -> #REF! | K47: =E47*CAOP!I47 -> #REF! | L47: =E47*CAOP!J47 -> #REF! | M47: =E47*CAOP!K47 -> #REF! | N47: =E47*CAOP!L47 -> #REF! | O47: =E47*CAOP!M47 -> #REF! | Q47: =SUM(F47:O47) -> #REF! | R47: =E47-Q47 -> #REF!
B48: 03.05 | C48: CERCO PARA PUNTO DE ACOPIO | D48: m | E48: 384 | F48: =E48*CAOP!D48 -> #REF! | G48: =E48*CAOP!E48 -> #REF! | H48: =E48*CAOP!F48 -> #REF! | I48: =E48*CAOP!G48 -> #REF! | J48: =E48*CAOP!H48 -> #REF! | K48: =E48*CAOP!I48 -> #REF! | L48: =E48*CAOP!J48 -> #REF! | M48: =E48*CAOP!K48 -> #REF! | N48: =E48*CAOP!L48 -> #REF! | O48: =E48*CAOP!M48 -> #REF! | Q48: =SUM(F48:O48) -> #REF! | R48: =E48-Q48 -> #REF!
B49: 03.06 | C49: PORTON PUNTO DE ACOPIO | D49: und | E49: 1 | F49: =E49*CAOP!D49 -> #REF! | G49: =E49*CAOP!E49 -> #REF! | H49: =E49*CAOP!F49 -> #REF! | I49: =E49*CAOP!G49 -> #REF! | J49: =E49*CAOP!H49 -> #REF! | K49: =E49*CAOP!I49 -> #REF! | L49: =E49*CAOP!J49 -> #REF! | M49: =E49*CAOP!K49 -> #REF! | N49: =E49*CAOP!L49 -> #REF! | O49: =E49*CAOP!M49 -> #REF! | Q49: =SUM(F49:O49) -> #REF! | R49: =E49-Q49 -> #REF!
B50: 03.07 | C50: CASETA DE GUARDIANÍA | D50: mes | E50: 9 | F50: =E50*CAOP!D50 -> #REF! | G50: =E50*CAOP!E50 -> #REF! | H50: =E50*CAOP!F50 -> #REF! | I50: =E50*CAOP!G50 -> #REF! | J50: =E50*CAOP!H50 -> #REF! | K50: =E50*CAOP!I50 -> #REF! | L50: =E50*CAOP!J50 -> #REF! | M50: =E50*CAOP!K50 -> #REF! | N50: =E50*CAOP!L50 -> #REF! | O50: =E50*CAOP!M50 -> #REF! | Q50: =SUM(F50:O50) -> #REF! | R50: =E50-Q50 -> #REF!
B51: 04 | C51: ACCESO A COMPONENTE 4 - CANAL JESUS MARIA | Q51: =SUM(F51:O51) -> 0 | R51: =E51-Q51 -> 0
B52: 04.01 | C52: ACCESO 01 | Q52: =SUM(F52:O52) -> 0 | R52: =E52-Q52 -> 0
B53: 04.01.01 | C53: TRAZO Y REPLANTEO PARA OBRAS VIALES | D53: km | E53: 1.31 | F53: =E53*CAOP!D53 -> #REF! | G53: =E53*CAOP!E53 -> #REF! | H53: =E53*CAOP!F53 -> #REF! | I53: =E53*CAOP!G53 -> #REF! | J53: =E53*CAOP!H53 -> #REF! | K53: =E53*CAOP!I53 -> #REF! | L53: =E53*CAOP!J53 -> #REF! | M53: =E53*CAOP!K53 -> #REF! | N53: =E53*CAOP!L53 -> #REF! | O53: =E53*CAOP!M53 -> #REF! | Q53: =SUM(F53:O53) -> #REF! | R53: =E53-Q53 -> #REF!
B54: 04.01.02 | C54: EXCAVACION C/MAQ. EN TERRENO NORMAL H<=2M | D54: m3 | E54: 13890.8 | F54: =E54*CAOP!D54 -> #REF! | G54: =E54*CAOP!E54 -> #REF! | H54: =E54*CAOP!F54 -> #REF! | I54: =E54*CAOP!G54 -> #REF! | J54: =E54*CAOP!H54 -> #REF! | K54: =E54*CAOP!I54 -> #REF! | L54: =E54*CAOP!J54 -> #REF! | M54: =E54*CAOP!K54 -> #REF! | N54: =E54*CAOP!L54 -> #REF! | O54: =E54*CAOP!M54 -> #REF! | Q54: =SUM(F54:O54) -> #REF! | R54: =E54-Q54 -> #REF!
B55: 04.01.03 | C55: ACARREO DE MATERIAL PROVENIENTE DE EXCAVACIONES, D<= 1KM | D55: m3-km | E55: 13890.8 | F55: =E55*CAOP!D55 -> #REF! | G55: =E55*CAOP!E55 -> #REF! | H55: =E55*CAOP!F55 -> #REF! | I55: =E55*CAOP!G55 -> #REF! | J55: =E55*CAOP!H55 -> #REF! | K55: =E55*CAOP!I55 -> #REF! | L55: =E55*CAOP!J55 -> #REF! | M55: =E55*CAOP!K55 -> #REF! | N55: =E55*CAOP!L55 -> #REF! | O55: =E55*CAOP!M55 -> #REF! | Q55: =SUM(F55:O55) -> #REF! | R55: =E55-Q55 -> #REF!
...

Sheet CURVA S
D1: CURVA S DEL PAQUETE 08
D3: “CONSTRUCCIÓN DEL SISTEMA DE DRENAJE URBANO EN EL SECTOR JESÚS MARÍA – CANAL Y OBRAS DE ESTABILIZACIÓN EN LAS LADERAS DEL SECTOR JESÚS MARÍA (PAQUETE 08)”
B5: MES | C5: MONTO | E5: PORCENTAJE
C6: PARCIAL (S/) | D6: ACUMULADO (S/) | E6: PARCIAL (%) | F6: ACUMULADO (%)
B7: 1 | C7: {=TRANSPOSE(PPTO!#REF!)} -> #REF! | D7: =+C7 -> #REF! | E7: =+C7/D$16 -> #REF! | F7: =E7 -> #REF!
B8: 2 | D8: =+C8+D7 -> #REF! | E8: =+C8/D$16 -> #REF! | F8: =+E8+F7 -> #REF!
B9: 3 | D9: =+C9+D8 -> #REF! | E9: =+C9/D$16 -> #REF! | F9: =+E9+F8 -> #REF!
B10: 4 | D10: =+C10+D9 -> #REF! | E10: =+C10/D$16 -> #REF! | F10: =+E10+F9 -> #REF!
B11: 5 | D11: =+C11+D10 -> #REF! | E11: =+C11/D$16 -> #REF! | F11: =+E11+F10 -> #REF!
B12: 6 | D12: =+C12+D11 -> #REF! | E12: =+C12/D$16 -> #REF! | F12: =+E12+F11 -> #REF!
B13: 7 | D13: =+C13+D12 -> #REF! | E13: =+C13/D$16 -> #REF! | F13: =+E13+F12 -> #REF!
B14: 8 | D14: =+C14+D13 -> #REF! | E14: =+C14/D$16 -> #REF! | F14: =+E14+F13 -> #REF!
B15: 9 | D15: =+C15+D14 -> #REF! | E15: =+C15/D$16 -> #REF! | F15: =+E15+F14 -> #REF!
B16: 10 | D16: =+C16+D15 -> #REF! | E16: =+C16/D$16 -> #REF! | F16: =+E16+F15 -> #REF!
